<?xml version="1.0" encoding="UTF-8"?>
<!-- Generated by org.testng.reporters.JUnitXMLReporter -->
<testsuite hostname="DESKTOP-A6EU9LL" ignored="0" name="test" tests="3" failures="2" timestamp="04 九月 2020 08:18:13 GMT" time="0.036" errors="0">
  <testcase name="logdemo" time="0.009" classname="com.test.extend.demo.TestMethodDemo">
    <failure type="java.lang.RuntimeException" message="这是我自己的运行时异常">
      <![CDATA[java.lang.RuntimeException: 这是我自己的运行时异常
	at com.test.extend.demo.TestMethodDemo.logdemo(TestMethodDemo.java:21)
	at com.intellij.rt.testng.IDEARemoteTestNG.run(IDEARemoteTestNG.java:66)
	at com.intellij.rt.testng.RemoteTestNGStarter.main(RemoteTestNGStarter.java:109)
... Removed 22 stack frames]]>
    </failure>
  </testcase> <!-- logdemo -->
  <testcase name="test1" time="0.002" classname="com.test.extend.demo.TestMethodDemo">
    <failure type="java.lang.AssertionError" message="expected [2] but found [1]">
      <![CDATA[java.lang.AssertionError: expected [2] but found [1]
	at com.test.extend.demo.TestMethodDemo.test1(TestMethodDemo.java:10)
	at com.intellij.rt.testng.IDEARemoteTestNG.run(IDEARemoteTestNG.java:66)
	at com.intellij.rt.testng.RemoteTestNGStarter.main(RemoteTestNGStarter.java:109)
... Removed 28 stack frames]]>
    </failure>
  </testcase> <!-- test1 -->
  <testcase name="test2" time="0.0" classname="com.test.extend.demo.TestMethodDemo"/>
</testsuite> <!-- test -->
